Workbook
Name k_coBillions: controlTables!$D$219
Name k_coMillions: controlTables!$D$220
Name k_coThousands: controlTables!$D$221
Name list_co_gcms: co_models[model_id]
Name list_coimpactYearOptions: OFFSET( INDIRECT( ADDRESS( ROW( co_impactYears[[#Headers],[row_id]] ), COLUMN(co_impactYears[[#Headers],[2090]]), , , "DropDownMenus" ) ), 1, 0, mv_coNum_impactYears, 1 )
Name loc_coAdaptations: co_variants[[#Headers],[row_id]]
Name loc_coConstants: co_constants[[#Headers],[row_id]]
Name loc_coImpactTypes: co_impactTypes[[#Headers],[row_id]]
Name loc_coImpactYears: co_impactYears[[#Headers],[row_id]]
Name loc_coInputScenarioInfo: co_inputScenarioInfo[[#Headers],[row_id]]
Name loc_colorLegend: controlTables!$C$16
Name loc_coModels: co_models[[#Headers],[row_id]]
Name loc_coModelTypes: co_modelTypes[[#Headers],[row_id]]
Name loc_controlTOC: controlTables!$B$1
Name loc_coRegions: co_regions[[#Headers],[row_id]]
Name loc_coScalars: co_scalarInfo[[#Headers],[row_id]]
Name loc_coSectors: co_sectors[[#Headers],[row_id]]
Name loc_coStates: co_impactYears[[#Headers],[row_id]]
Name loc_econMultipliers: co_econMultipliers[[#Headers],[row_id]]
Name num_gcms: MAX(co_models[row_id])
Name num_gcms: MAX(co_models[row_id])
Name SectorDropDown: controlTables!$D$21:$D$32
Name SectorDropDown_1: controlTables!$D$21:$D$37

Sheet ReadMe
B9: Worksheet | C9: Description
B10: tableNames | C10: Table for tracking of tables in "controlTables" tab, which is used by the R package to import function inputs. Additional notes are provided in the "notes" field.
B11: controlTables | C11: Tables used for documentation of sectors parameters and to define sector processing in the R package. The table of contents at the top of the worksheet lists all of the tables included in the worksheet. Narrative information for each sector and for general framework setup can be found in the Temperature Binning Framework documentation.
B12: defaultScenario | C12: Worksheet for user inputs to R tool. Expand group (see “+” to right) for field descriptions
C13: Field
C14: row_id
C15: year
C16: temp_C_conus
C17: gdp_usd
C18: pop_Midwest
C19: pop_Northeast
C20: pop_Northern.Plains
C21: pop_Northwest
C22: pop_Southeast
C23: pop_Southern.Plains
C24: pop_Southwest
B25: scalarData | C25: Scalars and adjustment factors applied to temperature or GMSL-binned data for inclusion of socioeconomic impact drivers or other time dependent factors. Expand group (see “+” to right) for field descriptions. See Appendix A of the Documentation Report for more information on these values.
C26: Field
C27: row_id
C28: scalarType
C29: scalarLabel
C30: scalarName
C31: region
C32: year
C33: value
B34: scaledImpacts | C34: Temperature or GMSL-binned data. Impacts estimates are scaled where appropriate to remove time-dependencies. Expand group (see “+” to right) for field descriptions. See Appendix A of the Documentation Report for more information on these values.
C35: Field
C36: row_id
C37: output_lookupID
C38: sector
C39: model
C40: modelUnitValue
C41: impactYear
C42: adaptation
C43: impactType
C44: outputRowID
C45: Midwest
C46: Northeast
... C51: Southwest

Sheet tableNames
A1: tableNames | B1: This worksheet contains the names of data tables to import into R
B3: ID | C3: Table Name | D3: Import | E3: Worksheet | F3: ID_columnName | G3: Header Row | H3: Number of Data Rows | I3: Last Row | J3: id_colIndex | K3: last_colIndex | L3: num_tableCols | M3: excludeCol_ids | N3: Notes
B4: =ROW( doc_tablesList[[#This Row],[ID]] ) - ROW(doc_tablesList[[#Headers],[ID]] ) -> 1 | C4: co_sectors | D4: 1 | E4: controlTables | F4: ="row_id" -> row_id | G4: {=INDEX( ROW( INDIRECT( _xlfn.TEXTJOIN( "", , doc_tablesList[[#This Row],[Table Name]], "[[#Headers],[", doc_tablesList[[#This Row],[ID_columnName]], "]]" ) ) ), 1 )} -> 20 | H4: =MAX( INDIRECT( _xlfn.TEXTJOIN( "", , doc_tablesList[[#This Row],[Table Name]], "[", doc_tablesList[[#This Row],[ID_columnName]], "]" ) ) ) -> 25 | I4: =doc_tablesList[[#This Row],[Number of Data Rows]] + doc_tablesList[[#This Row],[Header Row]] -> 45 | J4: {=INDEX( COLUMN( INDIRECT( doc_tablesList[[#This Row],[Table Name]] & "[" & doc_tablesList[[#This Row],[ID_columnName]] & "]" ) ), 1 )} -> 2 | K4: {=MAX( COLUMN( INDIRECT( doc_tablesList[[#This Row],[Table Name]] ) ) )} -> 17 | L4: =doc_tablesList[[#This Row],[last_colIndex]] - doc_tablesList[[#This Row],[id_colIndex]] + 1 -> 16 | M4: {=_xlfn.TEXTJOIN( ", ", , COLUMN( co_sectors[[#Headers],[interpolateEstimateYears]] ) - doc_tablesList[[#This Row],[id_colIndex]] + 1, COLUMN( co_sectors[[#Headers],[Number of variants]:[Number of scaled impact rows per region]] ) - doc_tablesList[[#This Row],[id_colIndex]] + 1 )} -> 7, 11, 12, 13, 14, 15, 16 | N4: Table of sector names and labels. Added variants impact years, and impact types list (columns 7-9), which the R Tool filters out.
B5: =ROW( doc_tablesList[[#This Row],[ID]] ) - ROW(doc_tablesList[[#Headers],[ID]] ) -> 2 | C5: scalarDataframe | D5: 1 | E5: scalarData | F5: ="row_id" -> row_id | G5: {=INDEX( ROW( INDIRECT( _xlfn.TEXTJOIN( "", , doc_tablesList[[#This Row],[Table Name]], "[[#Headers],[", doc_tablesList[[#This Row],[ID_columnName]], "]]" ) ) ), 1 )} -> 1 | H5: =MAX( INDIRECT( _xlfn.TEXTJOIN( "", , doc_tablesList[[#This Row],[Table Name]], "[", doc_tablesList[[#This Row],[ID_columnName]], "]" ) ) ) -> 1489 | I5: =doc_tablesList[[#This Row],[Number of Data Rows]] + doc_tablesList[[#This Row],[Header Row]] -> 1490 | J5: {=INDEX( COLUMN( INDIRECT( doc_tablesList[[#This Row],[Table Name]] & "[" & doc_tablesList[[#This Row],[ID_columnName]] & "]" ) ), 1 )} -> 1 | K5: {=MAX( COLUMN( INDIRECT( doc_tablesList[[#This Row],[Table Name]] ) ) )} -> 7 | L5: =doc_tablesList[[#This Row],[last_colIndex]] - doc_tablesList[[#This Row],[id_colIndex]] + 1 -> 7 | N5: Table of default economic scalars.
B6: =ROW( doc_tablesList[[#This Row],[ID]] ) - ROW(doc_tablesList[[#Headers],[ID]] ) -> 3 | C6: data_scaledImpacts | D6: 1 | E6: scaledImpacts | F6: ="row_id" -> row_id | G6: {=INDEX( ROW( INDIRECT( _xlfn.TEXTJOIN( "", , doc_tablesList[[#This Row],[Table Name]], "[[#Headers],[", doc_tablesList[[#This Row],[ID_columnName]], "]]" ) ) ), 1 )} -> 1 | H6: =MAX( INDIRECT( _xlfn.TEXTJOIN( "", , doc_tablesList[[#This Row],[Table Name]], "[", doc_tablesList[[#This Row],[ID_columnName]], "]" ) ) ) -> 3073 | I6: =doc_tablesList[[#This Row],[Number of Data Rows]] + doc_tablesList[[#This Row],[Header Row]] -> 3074 | J6: {=INDEX( COLUMN( INDIRECT( doc_tablesList[[#This Row],[Table Name]] & "[" & doc_tablesList[[#This Row],[ID_columnName]] & "]" ) ), 1 )} -> 1 | K6: {=MAX( COLUMN( INDIRECT( doc_tablesList[[#This Row],[Table Name]] ) ) )} -> 16 | L6: =doc_tablesList[[#This Row],[last_colIndex]] - doc_tablesList[[#This Row],[id_colIndex]] + 1 -> 16 | M6: =_xlfn.TEXTJOIN( ", ", , COLUMN( data_scaledImpacts[[#Headers],[output_lookupID]] ), COLUMN( data_scaledImpacts[[#Headers],[outputRowID]] ) - doc_tablesList[[#This Row],[id_colIndex]] + 1 ) -> 2, 9 | N6: Table with temperature-binned, scaled impacts
B7: =ROW( doc_tablesList[[#This Row],[ID]] ) - ROW(doc_tablesList[[#Headers],[ID]] ) -> 4 | C7: co_defaultScenario | D7: 1 | E7: defaultScenario | F7: ="row_id" -> row_id | G7: {=INDEX( ROW( INDIRECT( _xlfn.TEXTJOIN( "", , doc_tablesList[[#This Row],[Table Name]], "[[#Headers],[", doc_tablesList[[#This Row],[ID_columnName]], "]]" ) ) ), 1 )} -> 3 | H7: =MAX( INDIRECT( _xlfn.TEXTJOIN( "", , doc_tablesList[[#This Row],[Table Name]], "[", doc_tablesList[[#This Row],[ID_columnName]], "]" ) ) ) -> 17 | I7: =doc_tablesList[[#This Row],[Number of Data Rows]] + doc_tablesList[[#This Row],[Header Row]] -> 20 | J7: {=INDEX( COLUMN( INDIRECT( doc_tablesList[[#This Row],[Table Name]] & "[" & doc_tablesList[[#This Row],[ID_columnName]] & "]" ) ), 1 )} -> 2 | K7: {=MAX( COLUMN( INDIRECT( doc_tablesList[[#This Row],[Table Name]] ) ) )} -> 11 | L7: =doc_tablesList[[#This Row],[last_colIndex]] - doc_tablesList[[#This Row],[id_colIndex]] + 1 -> 10 | N7: Table with default values for CONUS temperatures, GDP, and regional population
B8: =ROW( doc_tablesList[[#This Row],[ID]] ) - ROW(doc_tablesList[[#Headers],[ID]] ) -> 5 | C8: co_defaultTemps | D8: 1 | E8: defaultScenario | F8: ="row_id" -> row_id | G8: {=INDEX( ROW( INDIRECT( _xlfn.TEXTJOIN( "", , doc_tablesList[[#This Row],[Table Name]], "[[#Headers],[", doc_tablesList[[#This Row],[ID_columnName]], "]]" ) ) ), 1 )} -> 22 | H8: =MAX( INDIRECT( _xlfn.TEXTJOIN( "", , doc_tablesList[[#This Row],[Table Name]], "[", doc_tablesList[[#This Row],[ID_columnName]], "]" ) ) ) -> 91 | I8: =doc_tablesList[[#This Row],[Number of Data Rows]] + doc_tablesList[[#This Row],[Header Row]] -> 113 | J8: {=INDEX( COLUMN( INDIRECT( doc_tablesList[[#This Row],[Table Name]] & "[" & doc_tablesList[[#This Row],[ID_columnName]] & "]" ) ), 1 )} -> 2 | K8: {=MAX( COLUMN( INDIRECT( doc_tablesList[[#This Row],[Table Name]] ) ) )} -> 4 | L8: =doc_tablesList[[#This Row],[last_colIndex]] - doc_tablesList[[#This Row],[id_colIndex]] + 1 -> 3 | N8: Table with default temperatures
B9: =ROW( doc_tablesList[[#This Row],[ID]] ) - ROW(doc_tablesList[[#Headers],[ID]] ) -> 6 | C9: co_variants | D9: 1 | E9: controlTables | F9: ="row_id" -> row_id | G9: {=INDEX( ROW( INDIRECT( _xlfn.TEXTJOIN( "", , doc_tablesList[[#This Row],[Table Name]], "[[#Headers],[", doc_tablesList[[#This Row],[ID_columnName]], "]]" ) ) ), 1 )} -> 80 | H9: =MAX( INDIRECT( _xlfn.TEXTJOIN( "", , doc_tablesList[[#This Row],[Table Name]], "[", doc_tablesList[[#This Row],[ID_columnName]], "]" ) ) ) -> 42 | I9: =doc_tablesList[[#This Row],[Number of Data Rows]] + doc_tablesList[[#This Row],[Header Row]] -> 122 | J9: {=INDEX( COLUMN( INDIRECT( doc_tablesList[[#This Row],[Table Name]] & "[" & doc_tablesList[[#This Row],[ID_columnName]] & "]" ) ), 1 )} -> 2 | K9: {=MAX( COLUMN( INDIRECT( doc_tablesList[[#This Row],[Table Name]] ) ) )} -> 11 | L9: =doc_tablesList[[#This Row],[last_colIndex]] - doc_tablesList[[#This Row],[id_colIndex]] + 1 -> 10 | M9: =_xlfn.TEXTJOIN( ", ", , COLUMN( co_variants[[#Headers],[check_data]] ) - doc_tablesList[[#This Row],[id_colIndex]] + 1, COLUMN( co_variants[[#Headers],[subImpacts]] ) - doc_tablesList[[#This Row],[id_colIndex]] + 1 ) -> 9, 10 | N9: Table with variant information
B10: =ROW( doc_tablesList[[#This Row],[ID]] ) - ROW(doc_tablesList[[#Headers],[ID]] ) -> 7 | C10: co_impactYears | D10: 1 | E10: controlTables | F10: ="row_id" -> row_id | G10: {=INDEX( ROW( INDIRECT( _xlfn.TEXTJOIN( "", , doc_tablesList[[#This Row],[Table Name]], "[[#Headers],[", doc_tablesList[[#This Row],[ID_columnName]], "]]" ) ) ), 1 )} -> 49 | H10: =MAX( INDIRECT( _xlfn.TEXTJOIN( "", , doc_tablesList[[#This Row],[Table Name]], "[", doc_tablesList[[#This Row],[ID_columnName]], "]" ) ) ) -> 25 | I10: =doc_tablesList[[#This Row],[Number of Data Rows]] + doc_tablesList[[#This Row],[Header Row]] -> 74 | J10: {=INDEX( COLUMN( INDIRECT( doc_tablesList[[#This Row],[Table Name]] & "[" & doc_tablesList[[#This Row],[ID_columnName]] & "]" ) ), 1 )} -> 2 | K10: {=MAX( COLUMN( INDIRECT( doc_tablesList[[#This Row],[Table Name]] ) ) )} -> 6 | L10: =doc_tablesList[[#This Row],[last_colIndex]] - doc_tablesList[[#This Row],[id_colIndex]] + 1 -> 5 | N10: Table with impact year information
B11: =ROW( doc_tablesList[[#This Row],[ID]] ) - ROW(doc_tablesList[[#Headers],[ID]] ) -> 8 | C11: co_impactTypes | D11: 1 | E11: controlTables | F11: ="row_id" -> row_id | G11: {=INDEX( ROW( INDIRECT( _xlfn.TEXTJOIN( "", , doc_tablesList[[#This Row],[Table Name]], "[[#Headers],[", doc_tablesList[[#This Row],[ID_columnName]], "]]" ) ) ), 1 )} -> 126 | H11: =MAX( INDIRECT( _xlfn.TEXTJOIN( "", , doc_tablesList[[#This Row],[Table Name]], "[", doc_tablesList[[#This Row],[ID_columnName]], "]" ) ) ) -> 43 | I11: =doc_tablesList[[#This Row],[Number of Data Rows]] + doc_tablesList[[#This Row],[Header Row]] -> 169 | J11: {=INDEX( COLUMN( INDIRECT( doc_tablesList[[#This Row],[Table Name]] & "[" & doc_tablesList[[#This Row],[ID_columnName]] & "]" ) ), 1 )} -> 2 | K11: {=MAX( COLUMN( INDIRECT( doc_tablesList[[#This Row],[Table Name]] ) ) )} -> 21 | L11: =doc_tablesList[[#This Row],[last_colIndex]] - doc_tablesList[[#This Row],[id_colIndex]] + 1 -> 20 | M11: {=_xlfn.TEXTJOIN( ", ", , COLUMN( co_impactTypes[[#Headers],[check_data]:[check_physScalar]] ) - doc_tablesList[[#This Row],[id_colIndex]] + 1 )} -> 17, 18, 19, 20 | N11: Table with impact type information
B12: =ROW( doc_tablesList[[#This Row],[ID]] ) - ROW(doc_tablesList[[#Headers],[ID]] ) -> 9 | C12: co_scalarInfo | D12: 1 | E12: controlTables | F12: ="row_id" -> row_id | G12: {=INDEX( ROW( INDIRECT( _xlfn.TEXTJOIN( "", , doc_tablesList[[#This Row],[Table Name]], "[[#Headers],[", doc_tablesList[[#This Row],[ID_columnName]], "]]" ) ) ), 1 )} -> 174 | H12: =MAX( INDIRECT( _xlfn.TEXTJOIN( "", , doc_tablesList[[#This Row],[Table Name]], "[", doc_tablesList[[#This Row],[ID_columnName]], "]" ) ) ) -> 31 | I12: =doc_tablesList[[#This Row],[Number of Data Rows]] + doc_tablesList[[#This Row],[Header Row]] -> 205 | J12: {=INDEX( COLUMN( INDIRECT( doc_tablesList[[#This Row],[Table Name]] & "[" & doc_tablesList[[#This Row],[ID_columnName]] & "]" ) ), 1 )} -> 2 | K12: {=MAX( COLUMN( INDIRECT( doc_tablesList[[#This Row],[Table Name]] ) ) )} -> 11 | L12: =doc_tablesList[[#This Row],[last_colIndex]] - doc_tablesList[[#This Row],[id_colIndex]] + 1 -> 10 | M12: {=_xlfn.TEXTJOIN( ", ", , COLUMN( co_scalarInfo[[#Headers],[dataType]:[scalar_rows]]) - doc_tablesList[[#This Row],[id_colIndex]] + 1 )} -> 8, 9, 10 | N12: Table with information about scalars
B13: =ROW( doc_tablesList[[#This Row],[ID]] ) - ROW(doc_tablesList[[#Headers],[ID]] ) -> 10 | C13: co_regions | D13: 1 | E13: controlTables | F13: ="row_id" -> row_id | G13: {=INDEX( ROW( INDIRECT( _xlfn.TEXTJOIN( "", , doc_tablesList[[#This Row],[Table Name]], "[[#Headers],[", doc_tablesList[[#This Row],[ID_columnName]], "]]" ) ) ), 1 )} -> 252 | H13: =MAX( INDIRECT( _xlfn.TEXTJOIN( "", , doc_tablesList[[#This Row],[Table Name]], "[", doc_tablesList[[#This Row],[ID_columnName]], "]" ) ) ) -> 7 | I13: =doc_tablesList[[#This Row],[Number of Data Rows]] + doc_tablesList[[#This Row],[Header Row]] -> 259 | J13: {=INDEX( COLUMN( INDIRECT( doc_tablesList[[#This Row],[Table Name]] & "[" & doc_tablesList[[#This Row],[ID_columnName]] & "]" ) ), 1 )} -> 2 | K13: {=MAX( COLUMN( INDIRECT( doc_tablesList[[#This Row],[Table Name]] ) ) )} -> 5 | L13: =doc_tablesList[[#This Row],[last_colIndex]] - doc_tablesList[[#This Row],[id_colIndex]] + 1 -> 4 | N13: Table with information about regions
B14: =ROW( doc_tablesList[[#This Row],[ID]] ) - ROW(doc_tablesList[[#Headers],[ID]] ) -> 11 | C14: co_models | D14: 1 | E14: controlTables | F14: ="row_id" -> row_id | G14: {=INDEX( ROW( INDIRECT( _xlfn.TEXTJOIN( "", , doc_tablesList[[#This Row],[Table Name]], "[[#Headers],[", doc_tablesList[[#This Row],[ID_columnName]], "]]" ) ) ), 1 )} -> 233 | H14: =MAX( INDIRECT( _xlfn.TEXTJOIN( "", , doc_tablesList[[#This Row],[Table Name]], "[", doc_tablesList[[#This Row],[ID_columnName]], "]" ) ) ) -> 14 | I14: =doc_tablesList[[#This Row],[Number of Data Rows]] + doc_tablesList[[#This Row],[Header Row]] -> 247 | J14: {=INDEX( COLUMN( INDIRECT( doc_tablesList[[#This Row],[Table Name]] & "[" & doc_tablesList[[#This Row],[ID_columnName]] & "]" ) ), 1 )} -> 2 | K14: {=MAX( COLUMN( INDIRECT( doc_tablesList[[#This Row],[Table Name]] ) ) )} -> 8 | L14: =doc_tablesList[[#This Row],[last_colIndex]] - doc_tablesList[[#This Row],[id_colIndex]] + 1 -> 7 | N14: Table with information about GCMs
B15: =ROW( doc_tablesList[[#This Row],[ID]] ) - ROW(doc_tablesList[[#Headers],[ID]] ) -> 12 | C15: co_econMultipliers | D15: 1 | E15: controlTables | F15: ="row_id" -> row_id | G15: {=INDEX( ROW( INDIRECT( _xlfn.TEXTJOIN( "", , doc_tablesList[[#This Row],[Table Name]], "[[#Headers],[", doc_tablesList[[#This Row],[ID_columnName]], "]]" ) ) ), 1 )} -> 210 | H15: =MAX( INDIRECT( _xlfn.TEXTJOIN( "", , doc_tablesList[[#This Row],[Table Name]], "[", doc_tablesList[[#This Row],[ID_columnName]], "]" ) ) ) -> 3 | I15: =doc_tablesList[[#This Row],[Number of Data Rows]] + doc_tablesList[[#This Row],[Header Row]] -> 213 | J15: {=INDEX( COLUMN( INDIRECT( doc_tablesList[[#This Row],[Table Name]] & "[" & doc_tablesList[[#This Row],[ID_columnName]] & "]" ) ), 1 )} -> 2 | K15: {=MAX( COLUMN( INDIRECT( doc_tablesList[[#This Row],[Table Name]] ) ) )} -> 5 | L15: =doc_tablesList[[#This Row],[last_colIndex]] - doc_tablesList[[#This Row],[id_colIndex]] + 1 -> 4 | M15: =_xlfn.TEXTJOIN( ", ", , COLUMN( co_econMultipliers[[#Headers],[valueYear]] ) - doc_tablesList[[#This Row],[id_colIndex]] + 1 ) -> 4 | N15: Table with information about economic multipliers
B16: =ROW( doc_tablesList[[#This Row],[ID]] ) - ROW(doc_tablesList[[#Headers],[ID]] ) -> 13 | C16: co_modelTypes | D16: 1 | E16: controlTables | F16: ="row_id" -> row_id | G16: {=INDEX( ROW( INDIRECT( _xlfn.TEXTJOIN( "", , doc_tablesList[[#This Row],[Table Name]], "[[#Headers],[", doc_tablesList[[#This Row],[ID_columnName]], "]]" ) ) ), 1 )} -> 226 | H16: =MAX( INDIRECT( _xlfn.TEXTJOIN( "", , doc_tablesList[[#This Row],[Table Name]], "[", doc_tablesList[[#This Row],[ID_columnName]], "]" ) ) ) -> 2 | I16: =doc_tablesList[[#This Row],[Number of Data Rows]] + doc_tablesList[[#This Row],[Header Row]] -> 228 | J16: {=INDEX( COLUMN( INDIRECT( doc_tablesList[[#This Row],[Table Name]] & "[" & doc_tablesList[[#This Row],[ID_columnName]] & "]" ) ), 1 )} -> 2 | K16: {=MAX( COLUMN( INDIRECT( doc_tablesList[[#This Row],[Table Name]] ) ) )} -> 14 | L16: =doc_tablesList[[#This Row],[last_colIndex]] - doc_tablesList[[#This Row],[id_colIndex]] + 1 -> 13 | M16: {=_xlfn.TEXTJOIN( ", ", , COLUMN( co_modelTypes[[#Headers],[Number of levels]:[Number of models]] ) - doc_tablesList[[#This Row],[id_colIndex]] + 1 )} -> 12, 13 | N16: Table with information about model types (GCM vs SLR)
B17: =ROW( doc_tablesList[[#This Row],[ID]] ) - ROW(doc_tablesList[[#Headers],[ID]] ) -> 14 | C17: co_inputScenarioInfo | D17: 1 | E17: controlTables | F17: ="row_id" -> row_id | G17: {=INDEX( ROW( INDIRECT( _xlfn.TEXTJOIN( "", , doc_tablesList[[#This Row],[Table Name]], "[[#Headers],[", doc_tablesList[[#This Row],[ID_columnName]], "]]" ) ) ), 1 )} -> 264 | H17: =MAX( INDIRECT( _xlfn.TEXTJOIN( "", , doc_tablesList[[#This Row],[Table Name]], "[", doc_tablesList[[#This Row],[ID_columnName]], "]" ) ) ) -> 4 | I17: =doc_tablesList[[#This Row],[Number of Data Rows]] + doc_tablesList[[#This Row],[Header Row]] -> 268 | J17: {=INDEX( COLUMN( INDIRECT( doc_tablesList[[#This Row],[Table Name]] & "[" & doc_tablesList[[#This Row],[ID_columnName]] & "]" ) ), 1 )} -> 2 | K17: {=MAX( COLUMN( INDIRECT( doc_tablesList[[#This Row],[Table Name]] ) ) )} -> 12 | L17: =doc_tablesList[[#This Row],[last_colIndex]] - doc_tablesList[[#This Row],[id_colIndex]] + 1 -> 11 | N17: Table with information about input scenarios
B18: =ROW( doc_tablesList[[#This Row],[ID]] ) - ROW(doc_tablesList[[#Headers],[ID]] ) -> 15 | C18: slr_cm | D18: 1 | E18: slr_cm | F18: ="row_id" -> row_id | G18: {=INDEX( ROW( INDIRECT( _xlfn.TEXTJOIN( "", , doc_tablesList[[#This Row],[Table Name]], "[[#Headers],[", doc_tablesList[[#This Row],[ID_columnName]], "]]" ) ) ), 1 )} -> 1 | H18: =MAX( INDIRECT( _xlfn.TEXTJOIN( "", , doc_tablesList[[#This Row],[Table Name]], "[", doc_tablesList[[#This Row],[ID_columnName]], "]" ) ) ) -> 101 | I18: =doc_tablesList[[#This Row],[Number of Data Rows]] + doc_tablesList[[#This Row],[Header Row]] -> 102 | J18: {=INDEX( COLUMN( INDIRECT( doc_tablesList[[#This Row],[Table Name]] & "[" & doc_tablesList[[#This Row],[ID_columnName]] & "]" ) ), 1 )} -> 1 | K18: {=MAX( COLUMN( INDIRECT( doc_tablesList[[#This Row],[Table Name]] ) ) )} -> 9 | L18: =doc_tablesList[[#This Row],[last_colIndex]] - doc_tablesList[[#This Row],[id_colIndex]] + 1 -> 9 | N18: Table with heights in cm of SLR scenarios
B19: =ROW( doc_tablesList[[#This Row],[ID]] ) - ROW(doc_tablesList[[#Headers],[ID]] ) -> 16 | C19: slrImpacts | D19: 1 | E19: slrImpacts | F19: ="row_id" -> row_id | G19: {=INDEX( ROW( INDIRECT( _xlfn.TEXTJOIN( "", , doc_tablesList[[#This Row],[Table Name]], "[[#Headers],[", doc_tablesList[[#This Row],[ID_columnName]], "]]" ) ) ), 1 )} -> 1 | H19: =MAX( INDIRECT( _xlfn.TEXTJOIN( "", , doc_tablesList[[#This Row],[Table Name]], "[", doc_tablesList[[#This Row],[ID_columnName]], "]" ) ) ) -> 606 | I19: =doc_tablesList[[#This Row],[Number of Data Rows]] + doc_tablesList[[#This Row],[Header Row]] -> 607 | J19: {=INDEX( COLUMN( INDIRECT( doc_tablesList[[#This Row],[Table Name]] & "[" & doc_tablesList[[#This Row],[ID_columnName]] & "]" ) ), 1 )} -> 1 | K19: {=MAX( COLUMN( INDIRECT( doc_tablesList[[#This Row],[Table Name]] ) ) )} -> 48 | L19: =doc_tablesList[[#This Row],[last_colIndex]] - doc_tablesList[[#This Row],[id_colIndex]] + 1 -> 48 | N19: Table with SLR scaled impacts
B20: =ROW( doc_tablesList[[#This Row],[ID]] ) - ROW(doc_tablesList[[#Headers],[ID]] ) -> 17 | C20: testDev | D20: 1 | E20: testDev | F20: ="row_id" -> row_id | G20: {=INDEX( ROW( INDIRECT( _xlfn.TEXTJOIN( "", , doc_tablesList[[#This Row],[Table Name]], "[[#Headers],[", doc_tablesList[[#This Row],[ID_columnName]], "]]" ) ) ), 1 )} -> 3 | H20: =MAX( INDIRECT( _xlfn.TEXTJOIN( "", , doc_tablesList[[#This Row],[Table Name]], "[", doc_tablesList[[#This Row],[ID_columnName]], "]" ) ) ) -> 25 | I20: =doc_tablesList[[#This Row],[Number of Data Rows]] + doc_tablesList[[#This Row],[Header Row]] -> 28 | J20: {=INDEX( COLUMN( INDIRECT( doc_tablesList[[#This Row],[Table Name]] & "[" & doc_tablesList[[#This Row],[ID_columnName]] & "]" ) ), 1 )} -> 2 | K20: {=MAX( COLUMN( INDIRECT( doc_tablesList[[#This Row],[Table Name]] ) ) )} -> 5 | L20: =doc_tablesList[[#This Row],[last_colIndex]] - doc_tablesList[[#This Row],[id_colIndex]] + 1 -> 4 | N20: Table with information about tests
B21: =ROW( doc_tablesList[[#This Row],[ID]] ) - ROW(doc_tablesList[[#Headers],[ID]] ) -> 18 | C21: co_states | D21: 1 | E21: controlTables | F21: ="row_id" -> row_id | G21: {=INDEX( ROW( INDIRECT( _xlfn.TEXTJOIN( "", , doc_tablesList[[#This Row],[Table Name]], "[[#Headers],[", doc_tablesList[[#This Row],[ID_columnName]], "]]" ) ) ), 1 )} -> 273 | H21: =MAX( INDIRECT( _xlfn.TEXTJOIN( "", , doc_tablesList[[#This Row],[Table Name]], "[", doc_tablesList[[#This Row],[ID_columnName]], "]" ) ) ) -> 49 | I21: =doc_tablesList[[#This Row],[Number of Data Rows]] + doc_tablesList[[#This Row],[Header Row]] -> 322 | J21: {=INDEX( COLUMN( INDIRECT( doc_tablesList[[#This Row],[Table Name]] & "[" & doc_tablesList[[#This Row],[ID_columnName]] & "]" ) ), 1 )} -> 2 | K21: {=MAX( COLUMN( INDIRECT( doc_tablesList[[#This Row],[Table Name]] ) ) )} -> 6 | L21: =doc_tablesList[[#This Row],[last_colIndex]] - doc_tablesList[[#This Row],[id_colIndex]] + 1 -> 5 | N21: Table with information about states
B22: =ROW( doc_tablesList[[#This Row],[ID]] ) - ROW(doc_tablesList[[#Headers],[ID]] ) -> 19 | C22: co_slrScalars | D22: 1 | E22: controlTables | F22: row_id | G22: {=INDEX( ROW( INDIRECT( _xlfn.TEXTJOIN( "", , doc_tablesList[[#This Row],[Table Name]], "[[#Headers],[", doc_tablesList[[#This Row],[ID_columnName]], "]]" ) ) ), 1 )} -> 328 | H22: =MAX( INDIRECT( _xlfn.TEXTJOIN( "", , doc_tablesList[[#This Row],[Table Name]], "[", doc_tablesList[[#This Row],[ID_columnName]], "]" ) ) ) -> 2 | I22: =doc_tablesList[[#This Row],[Number of Data Rows]] + doc_tablesList[[#This Row],[Header Row]] -> 330 | J22: {=INDEX( COLUMN( INDIRECT( doc_tablesList[[#This Row],[Table Name]] & "[" & doc_tablesList[[#This Row],[ID_columnName]] & "]" ) ), 1 )} -> 2 | K22: {=MAX( COLUMN( INDIRECT( doc_tablesList[[#This Row],[Table Name]] ) ) )} -> 10 | L22: =doc_tablesList[[#This Row],[last_colIndex]] - doc_tablesList[[#This Row],[id_colIndex]] + 1 -> 9 | N22: Table with info about SLR scalars past 2090

Sheet testDev
A1: tableNames | B1: This worksheet contains the names of data tables to import into R
B3: row_id | C3: Table Name | D3: Changes if new sector added | E3: New sector changes
B4: =ROW( testDev[[#This Row],[row_id]] ) - ROW(testDev[[#Headers],[row_id]] ) -> 1 | C4: co_sectors | D4: Yes | E4: New rows for each new sector
B5: =ROW( testDev[[#This Row],[row_id]] ) - ROW(testDev[[#Headers],[row_id]] ) -> 2 | C5: scalarDataframe | D5: Maybe | E5: New rows if a new sector uses a new type of scalar. Can check if the new `co_impactTypes` has any scalars that aren't in the reference `co_scalarInfo` and, if so, we expect the new `scalarDataframe` to have new rows. Each new scalar will have at least one new row. Minimum number of new rows depends on the attributes of the scalar (e.g., whether national or regional, etc.)
B6: =ROW( testDev[[#This Row],[row_id]] ) - ROW(testDev[[#Headers],[row_id]] ) -> 3 | C6: data_scaledImpacts | D6: Yes | E6: New rows associated with the new sector if a sector is temperature-driven. Can check info from `co_sectors` to see if sector is temperature-driven (in which case, scaled impacts added to `data_scaledImpacts`) or SLR-driven (in which case, scaled impacts added to `slrImpacts`). Number of new rows will equal: Number of variants * Number of impact types * Number of impact years * Number of GCM models * Number of degrees (6)
B7: =ROW( testDev[[#This Row],[row_id]] ) - ROW(testDev[[#Headers],[row_id]] ) -> 4 | C7: co_defaultScenario | D7: No | E7: No changes expected for a new sector
B8: =ROW( testDev[[#This Row],[row_id]] ) - ROW(testDev[[#Headers],[row_id]] ) -> 5 | C8: co_defaultTemps | D8: No | E8: No changes expected for a new sector
B9: =ROW( testDev[[#This Row],[row_id]] ) - ROW(testDev[[#Headers],[row_id]] ) -> 6 | C9: co_variants | D9: Yes | E9: New rows for each new sector for each variant type (a sector without a named variant will still add a new row in this table)
B10: =ROW( testDev[[#This Row],[row_id]] ) - ROW(testDev[[#Headers],[row_id]] ) -> 7 | C10: co_impactYears | D10: Yes | E10: New rows for each new sector (a sector without specific impact years will still add a new row in this table)
B11: =ROW( testDev[[#This Row],[row_id]] ) - ROW(testDev[[#Headers],[row_id]] ) -> 8 | C11: co_impactTypes | D11: Yes | E11: New rows for each new sector, impact type, and variant (a sector without specific impact years will still add least one new row in this table)
B12: =ROW( testDev[[#This Row],[row_id]] ) - ROW(testDev[[#Headers],[row_id]] ) -> 9 | C12: co_scalarInfo | D12: Maybe | E12: New rows if a new sector uses a new type of scalar. Can check if the new `co_impactTypes` has any scalars that aren't in the reference `co_scalarInfo` and, if so, we expect the new `co_scalarInfo` to have new rows (number of new rows = number of new scalars).
B13: =ROW( testDev[[#This Row],[row_id]] ) - ROW(testDev[[#Headers],[row_id]] ) -> 10 | C13: co_regions | D13: No | E13: No changes expected for a new sector
B14: =ROW( testDev[[#This Row],[row_id]] ) - ROW(testDev[[#Headers],[row_id]] ) -> 11 | C14: co_models | D14: Maybe | E14: Sometimes new sectors have new models. We could specific the new model(s) at the time we run the "new sector" test
B15: =ROW( testDev[[#This Row],[row_id]] ) - ROW(testDev[[#Headers],[row_id]] ) -> 12 | C15: co_econMultipliers | D15: No | E15: In theory, yes, but generally, no. We haven't added a new econMultiplier in ages. So let's assume it is no for the purposes of developing the test and revisit this if there is a special case
... B28: =ROW( testDev[[#This Row],[row_id]] ) - ROW(testDev[[#Headers],[row_id]] ) -> 25 | C28: df_results0 | D28: Yes | E28: New rows for each new sector, impact type, variant, region, GCM model (including new models), etc. Will also add rows for any new GCM model for all other combinations

Sheet controlTables
B1: Table of Contents
C2: =OFFSET( INDIRECT( ADDRESS( ROW( co_sectors[[#Headers],[row_id]] ), COLUMN( co_sectors[[#Headers],[row_id]] ), , , ) ), -2, , 1, 1 ) -> Sectors Table | D2: Overview of sectors included in the model
C3: =OFFSET( INDIRECT( ADDRESS( ROW( co_impactYears[[#Headers],[row_id]] ), COLUMN( co_impactYears[[#Headers],[row_id]] ), , , ) ), -2, , 1, 1 ) -> Impact Year Estimates | D3: Overview of impact estimate years associated with each sector
C4: =OFFSET( INDIRECT( ADDRESS( ROW( co_variants[[#Headers],[row_id]] ), COLUMN( co_variants[[#Headers],[row_id]] ), , , ) ), -4, , 1, 1 ) -> Variants Table | D4: Overview of sector-adaptation combinations
C5: =OFFSET( INDIRECT( ADDRESS( ROW( co_impactTypes[[#Headers],[row_id]] ), COLUMN( co_impactTypes[[#Headers],[row_id]] ), , , ) ), -2, , 1, 1 ) -> Impact Types | D5: Overview of sector-impact type combinations
C6: =OFFSET( INDIRECT( ADDRESS( ROW( co_scalarInfo[[#Headers],[row_id]] ), COLUMN( co_scalarInfo[[#Headers],[row_id]] ), , , ) ), -2, , 1, 1 ) -> Scalar Information | D6: Overview of physical scalars, physical adjustments, damage adjustments, economic scalars, and economic multipliers.
C7: =OFFSET( INDIRECT( ADDRESS( ROW( co_econMultipliers[[#Headers],[row_id]] ), COLUMN( co_econMultipliers[[#Headers],[row_id]] ), , , ) ), -2, , 1, 1 ) -> Economic Multipliers | D7: Overview of economic multipliers
C8: =OFFSET( INDIRECT( ADDRESS( ROW( co_constants[[#Headers],[row_id]] ), COLUMN( co_constants[[#Headers],[row_id]] ), , , ) ), -2, , 1, 1 ) -> Constants | D8: Named constants
C9: =OFFSET( INDIRECT( ADDRESS( ROW( co_modelTypes[[#Headers],[row_id]] ), COLUMN( co_modelTypes[[#Headers],[row_id]] ), , , ) ), -2, , 1, 1 ) -> Model Types | D9: Temperature and SLR-binning model types
C10: =OFFSET( INDIRECT( ADDRESS( ROW( co_models[[#Headers],[row_id]] ), COLUMN( co_models[[#Headers],[row_id]] ), , , ) ), -2, , 1, 1 ) -> Binning Models | D10: Temperature and SLR-binning models (GCMs and SLR scenarios)
C11: =OFFSET( INDIRECT( ADDRESS( ROW( co_regions[[#Headers],[row_id]] ), COLUMN( co_regions[[#Headers],[row_id]] ), , , ) ), -2, , 1, 1 ) -> Regions | D11: List of regions
C12: =OFFSET( INDIRECT( ADDRESS( ROW( co_inputScenarioInfo[[#Headers],[row_id]] ), COLUMN( co_inputScenarioInfo[[#Headers],[row_id]] ), , , ) ), -2, , 1, 1 ) -> Input Scenario Information | D12: Information about input scenarios
C13: =OFFSET( INDIRECT( ADDRESS( ROW( co_states[[#Headers],[row_id]] ), COLUMN( co_states[[#Headers],[row_id]] ), , , ) ), -2, , 1, 1 ) -> States | D13: List of states
C14: =OFFSET( INDIRECT( ADDRESS( ROW( co_slrScalars[[#Headers],[row_id]] ), COLUMN( co_slrScalars[[#Headers],[row_id]] ), , , ) ), -3, , 1, 1 ) -> SLR Scalars | D14: Info on SLR scalars past 2090
C16: Color Legend | D16: Hard-coded value/included in model | E16: Calculated value | F16: Column used for record-keeping of data checks
B18: Sectors Table
B20: row_id | C20: sector_id | D20: sector_label | E20: include | F20: modelType | G20: byState | H20: interpolateEstimateYears | I20: variants | J20: impactYears | K20: impactTypes | L20: Number of variants | M20: Number of impact types | N20: Number of impact years | O20: Number of models | P20: Number of levels | Q20: Number of scaled impact rows per region
B21: =ROW( co_sectors[[#This Row],[row_id]] ) - ROW( co_sectors[[#Headers],[row_id]] ) -> 1 | C21: AirQuality | D21: Air Quality | E21: 1 | F21: gcm | G21: 1 | H21: {=IF( AND( SUMPRODUCT( co_impactYears[2010], --( co_sectors[[#This Row],[sector_id]] = co_impactYears[sector_id] ) ) > 1, SUMPRODUCT( co_impactYears[2090], --( co_sectors[[#This Row],[sector_id]] = co_impactYears[sector_id] ) ) > 1 ), 1, 0 )} -> 0 | I21: {=_xlfn.TEXTJOIN( ", ", 1, IF( OFFSET( INDIRECT( ADDRESS( ROW( co_variants[[#Headers],[row_id]] ), COLUMN( co_variants[[#Headers],[sector_id]] ), , , "controlTables" ) ), 1, 0, MAX( co_variants[row_id] ), 1 ) = co_sectors[[#This Row],[sector_id]], co_variants[variant_label], "" ) )} -> 2011 Emissions, 2040 Emissions | J21: =_xlfn.TEXTJOIN( ", ", 1, OFFSET( INDIRECT( ADDRESS( ROW( INDEX( co_impactYears[sector_id], MATCH( co_sectors[[#This Row],[sector_id]], co_impactYears[sector_id], 0 ) ) ), COLUMN( co_impactYears[[#Headers],[sector_id]] ), , , "controlTables" ) ), 0, 1, 1, 4 ) ) -> N/A | K21: {=_xlfn.TEXTJOIN( ", ", 1, IF( OFFSET( INDIRECT( ADDRESS( ROW( co_impactTypes[[#Headers],[row_id]] ), COLUMN( co_impactTypes[[#Headers],[sector_id]] ), , , "controlTables" ) ), 1, 0, MAX( co_impactTypes[row_id] ), 1 ) = co_sectors[[#This Row],[sector_id]], co_impactTypes[impactType_label], "" ) )} -> Ozone, PM2.5 | L21: {=SUMPRODUCT( --( co_sectors[[#This Row],[sector_id]] = co_variants[sector_id] ) )} -> 2 | M21: {=SUMPRODUCT( --( co_sectors[[#This Row],[sector_id]] = co_impactTypes[sector_id] ) )} -> 2 | N21: {=IF( INDEX( co_impactYears[N/A], MATCH( 1, --( co_sectors[[#This Row],[sector_id]] = co_impactYears[sector_id] ), 0 ) ) = "N/A", 1, 2 )} -> 1 | O21: {=INDEX( co_modelTypes[Number of models], MATCH( 1, --( co_sectors[[#This Row],[modelType]] = co_modelTypes[modelType_id] ), 0 ) ) + IF( co_sectors[[#This Row],[modelType]] = "gcm", 1, 0 )} -> 9 | P21: {=INDEX( co_modelTypes[Number of levels], MATCH( 1, --( co_sectors[[#This Row],[modelType]] = co_modelTypes[modelType_id] ), 0 ) )} -> 7 | Q21: =PRODUCT( co_sectors[[#This Row],[Number of variants]:[Number of levels]] ) -> 252
B22: =ROW( co_sectors[[#This Row],[row_id]] ) - ROW( co_sectors[[#Headers],[row_id]] ) -> 2 | C22: AsphaltRoads | D22: Asphalt Roads | E22: 1 | F22: gcm | G22: 1 | H22: {=IF( AND( SUMPRODUCT( co_impactYears[2010], --( co_sectors[[#This Row],[sector_id]] = co_impactYears[sector_id] ) ) > 1, SUMPRODUCT( co_impactYears[2090], --( co_sectors[[#This Row],[sector_id]] = co_impactYears[sector_id] ) ) > 1 ), 1, 0 )} -> 0 | I22: {=_xlfn.TEXTJOIN( ", ", 1, IF( OFFSET( INDIRECT( ADDRESS( ROW( co_variants[[#Headers],[row_id]] ), COLUMN( co_variants[[#Headers],[sector_id]] ), , , "controlTables" ) ), 1, 0, MAX( co_variants[row_id] ), 1 ) = co_sectors[[#This Row],[sector_id]], co_variants[variant_label], "" ) )} -> N/A | J22: =_xlfn.TEXTJOIN( ", ", 1, OFFSET( INDIRECT( ADDRESS( ROW( INDEX( co_impactYears[sector_id], MATCH( co_sectors[[#This Row],[sector_id]], co_impactYears[sector_id], 0 ) ) ), COLUMN( co_impactYears[[#Headers],[sector_id]] ), , , "controlTables" ) ), 0, 1, 1, 4 ) ) -> N/A | K22: {=_xlfn.TEXTJOIN( ", ", 1, IF( OFFSET( INDIRECT( ADDRESS( ROW( co_impactTypes[[#Headers],[row_id]] ), COLUMN( co_impactTypes[[#Headers],[sector_id]] ), , , "controlTables" ) ), 1, 0, MAX( co_impactTypes[row_id] ), 1 ) = co_sectors[[#This Row],[sector_id]], co_impactTypes[impactType_label], "" ) )} -> N/A | L22: {=SUMPRODUCT( --( co_sectors[[#This Row],[sector_id]] = co_variants[sector_id] ) )} -> 1 | M22: {=SUMPRODUCT( --( co_sectors[[#This Row],[sector_id]] = co_impactTypes[sector_id] ) )} -> 1 | N22: {=IF( INDEX( co_impactYears[N/A], MATCH( 1, --( co_sectors[[#This Row],[sector_id]] = co_impactYears[sector_id] ), 0 ) ) = "N/A", 1, 2 )} -> 1 | O22: {=INDEX( co_modelTypes[Number of models], MATCH( 1, --( co_sectors[[#This Row],[modelType]] = co_modelTypes[modelType_id] ), 0 ) ) + IF( co_sectors[[#This Row],[modelType]] = "gcm", 1, 0 )} -> 9 | P22: {=INDEX( co_modelTypes[Number of levels], MATCH( 1, --( co_sectors[[#This Row],[modelType]] = co_modelTypes[modelType_id] ), 0 ) )} -> 7 | Q22: =PRODUCT( co_sectors[[#This Row],[Number of variants]:[Number of levels]] ) -> 63
B23: =ROW( co_sectors[[#This Row],[row_id]] ) - ROW( co_sectors[[#Headers],[row_id]] ) -> 3 | C23: ATSExtremeTemp | D23: ATS Extreme Temperature | E23: 1 | F23: gcm | G23: 1 | H23: {=IF( AND( SUMPRODUCT( co_impactYears[2010], --( co_sectors[[#This Row],[sector_id]] = co_impactYears[sector_id] ) ) > 1, SUMPRODUCT( co_impactYears[2090], --( co_sectors[[#This Row],[sector_id]] = co_impactYears[sector_id] ) ) > 1 ), 1, 0 )} -> 0 | I23: {=_xlfn.TEXTJOIN( ", ", 1, IF( OFFSET( INDIRECT( ADDRESS( ROW( co_variants[[#Headers],[row_id]] ), COLUMN( co_variants[[#Headers],[sector_id]] ), , , "controlTables" ) ), 1, 0, MAX( co_variants[row_id] ), 1 ) = co_sectors[[#This Row],[sector_id]], co_variants[variant_label], "" ) )} -> Mean, Low Confidence Interval, High Confidence Interval | J23: =_xlfn.TEXTJOIN( ", ", 1, OFFSET( INDIRECT( ADDRESS( ROW( INDEX( co_impactYears[sector_id], MATCH( co_sectors[[#This Row],[sector_id]], co_impactYears[sector_id], 0 ) ) ), COLUMN( co_impactYears[[#Headers],[sector_id]] ), , , "controlTables" ) ), 0, 1, 1, 4 ) ) -> N/A | K23: {=_xlfn.TEXTJOIN( ", ", 1, IF( OFFSET( INDIRECT( ADDRESS( ROW( co_impactTypes[[#Headers],[row_id]] ), COLUMN( co_impactTypes[[#Headers],[sector_id]] ), , , "controlTables" ) ), 1, 0, MAX( co_impactTypes[row_id] ), 1 ) = co_sectors[[#This Row],[sector_id]], co_impactTypes[impactType_label], "" ) )} -> N/A | L23: {=SUMPRODUCT( --( co_sectors[[#This Row],[sector_id]] = co_variants[sector_id] ) )} -> 3 | M23: {=SUMPRODUCT( --( co_sectors[[#This Row],[sector_id]] = co_impactTypes[sector_id] ) )} -> 1 | N23: {=IF( INDEX( co_impactYears[N/A], MATCH( 1, --( co_sectors[[#This Row],[sector_id]] = co_impactYears[sector_id] ), 0 ) ) = "N/A", 1, 2 )} -> 1 | O23: {=INDEX( co_modelTypes[Number of models], MATCH( 1, --( co_sectors[[#This Row],[modelType]] = co_modelTypes[modelType_id] ), 0 ) ) + IF( co_sectors[[#This Row],[modelType]] = "gcm", 1, 0 )} -> 9 | P23: {=INDEX( co_modelTypes[Number of levels], MATCH( 1, --( co_sectors[[#This Row],[modelType]] = co_modelTypes[modelType_id] ), 0 ) )} -> 7 | Q23: =PRODUCT( co_sectors[[#This Row],[Number of variants]:[Number of levels]] ) -> 189
B24: =ROW( co_sectors[[#This Row],[row_id]] ) - ROW( co_sectors[[#Headers],[row_id]] ) -> 4 | C24: CILAgriculture | D24: CIL Agriculture | E24: 1 | F24: gcm | G24: 0 | H24: {=IF( AND( SUMPRODUCT( co_impactYears[2010], --( co_sectors[[#This Row],[sector_id]] = co_impactYears[sector_id] ) ) > 1, SUMPRODUCT( co_impactYears[2090], --( co_sectors[[#This Row],[sector_id]] = co_impactYears[sector_id] ) ) > 1 ), 1, 0 )} -> 0 | I24: {=_xlfn.TEXTJOIN( ", ", 1, IF( OFFSET( INDIRECT( ADDRESS( ROW( co_variants[[#Headers],[row_id]] ), COLUMN( co_variants[[#Headers],[sector_id]] ), , , "controlTables" ) ), 1, 0, MAX( co_variants[row_id] ), 1 ) = co_sectors[[#This Row],[sector_id]], co_variants[variant_label], "" ) )} -> With CO2 Fertilization, Without CO2 Fertilization | J24: =_xlfn.TEXTJOIN( ", ", 1, OFFSET( INDIRECT( ADDRESS( ROW( INDEX( co_impactYears[sector_id], MATCH( co_sectors[[#This Row],[sector_id]], co_impactYears[sector_id], 0 ) ) ), COLUMN( co_impactYears[[#Headers],[sector_id]] ), , , "controlTables" ) ), 0, 1, 1, 4 ) ) -> N/A | K24: {=_xlfn.TEXTJOIN( ", ", 1, IF( OFFSET( INDIRECT( ADDRESS( ROW( co_impactTypes[[#Headers],[row_id]] ), COLUMN( co_impactTypes[[#Headers],[sector_id]] ), , , "controlTables" ) ), 1, 0, MAX( co_impactTypes[row_id] ), 1 ) = co_sectors[[#This Row],[sector_id]], co_impactTypes[impactType_label], "" ) )} -> Cotton, Maize, Soybean, Wheat | L24: {=SUMPRODUCT( --( co_sectors[[#This Row],[sector_id]] = co_variants[sector_id] ) )} -> 2 | M24: {=SUMPRODUCT( --( co_sectors[[#This Row],[sector_id]] = co_impactTypes[sector_id] ) )} -> 4 | N24: {=IF( INDEX( co_impactYears[N/A], MATCH( 1, --( co_sectors[[#This Row],[sector_id]] = co_impactYears[sector_id] ), 0 ) ) = "N/A", 1, 2 )} -> 1 | O24: {=INDEX( co_modelTypes[Number of models], MATCH( 1, --( co_sectors[[#This Row],[modelType]] = co_modelTypes[modelType_id] ), 0 ) ) + IF( co_sectors[[#This Row],[modelType]] = "gcm", 1, 0 )} -> 9 | P24: {=INDEX( co_modelTypes[Number of levels], MATCH( 1, --( co_sectors[[#This Row],[modelType]] = co_modelTypes[modelType_id] ), 0 ) )} -> 7 | Q24: =PRODUCT( co_sectors[[#This Row],[Number of variants]:[Number of levels]] ) -> 504
B25: =ROW( co_sectors[[#This Row],[row_id]] ) - ROW( co_sectors[[#Headers],[row_id]] ) -> 5 | C25: CILCrime | D25: CIL Crime | E25: 1 | F25: gcm | G25: 0 | H25: {=IF( AND( SUMPRODUCT( co_impactYears[2010], --( co_sectors[[#This Row],[sector_id]] = co_impactYears[sector_id] ) ) > 1, SUMPRODUCT( co_impactYears[2090], --( co_sectors[[#This Row],[sector_id]] = co_impactYears[sector_id] ) ) > 1 ), 1, 0 )} -> 0 | I25: {=_xlfn.TEXTJOIN( ", ", 1, IF( OFFSET( INDIRECT( ADDRESS( ROW( co_variants[[#Headers],[row_id]] ), COLUMN( co_variants[[#Headers],[sector_id]] ), , , "controlTables" ) ), 1, 0, MAX( co_variants[row_id] ), 1 ) = co_sectors[[#This Row],[sector_id]], co_variants[variant_label], "" ) )} -> N/A | J25: =_xlfn.TEXTJOIN( ", ", 1, OFFSET( INDIRECT( ADDRESS( ROW( INDEX( co_impactYears[sector_id], MATCH( co_sectors[[#This Row],[sector_id]], co_impactYears[sector_id], 0 ) ) ), COLUMN( co_impactYears[[#Headers],[sector_id]] ), , , "controlTables" ) ), 0, 1, 1, 4 ) ) -> N/A | K25: {=_xlfn.TEXTJOIN( ", ", 1, IF( OFFSET( INDIRECT( ADDRESS( ROW( co_impactTypes[[#Headers],[row_id]] ), COLUMN( co_impactTypes[[#Headers],[sector_id]] ), , , "controlTables" ) ), 1, 0, MAX( co_impactTypes[row_id] ), 1 ) = co_sectors[[#This Row],[sector_id]], co_impactTypes[impactType_label], "" ) )} -> Property, Violent | L25: {=SUMPRODUCT( --( co_sectors[[#This Row],[sector_id]] = co_variants[sector_id] ) )} -> 1 | M25: {=SUMPRODUCT( --( co_sectors[[#This Row],[sector_id]] = co_impactTypes[sector_id] ) )} -> 2 | N25: {=IF( INDEX( co_impactYears[N/A], MATCH( 1, --( co_sectors[[#This Row],[sector_id]] = co_impactYears[sector_id] ), 0 ) ) = "N/A", 1, 2 )} -> 1 | O25: {=INDEX( co_modelTypes[Number of models], MATCH( 1, --( co_sectors[[#This Row],[modelType]] = co_modelTypes[modelType_id] ), 0 ) ) + IF( co_sectors[[#This Row],[modelType]] = "gcm", 1, 0 )} -> 9 | P25: {=INDEX( co_modelTypes[Number of levels], MATCH( 1, --( co_sectors[[#This Row],[modelType]] = co_modelTypes[modelType_id] ), 0 ) )} -> 7 | Q25: =PRODUCT( co_sectors[[#This Row],[Number of variants]:[Number of levels]] ) -> 126
B26: =ROW( co_sectors[[#This Row],[row_id]] ) - ROW( co_sectors[[#Headers],[row_id]] ) -> 6 | C26: CILExtremeTemp | D26: CIL Extreme Temperature | E26: 1 | F26: gcm | G26: 0 | H26: {=IF( AND( SUMPRODUCT( co_impactYears[2010], --( co_sectors[[#This Row],[sector_id]] = co_impactYears[sector_id] ) ) > 1, SUMPRODUCT( co_impactYears[2090], --( co_sectors[[#This Row],[sector_id]] = co_impactYears[sector_id] ) ) > 1 ), 1, 0 )} -> 0 | I26: {=_xlfn.TEXTJOIN( ", ", 1, IF( OFFSET( INDIRECT( ADDRESS( ROW( co_variants[[#Headers],[row_id]] ), COLUMN( co_variants[[#Headers],[sector_id]] ), , , "controlTables" ) ), 1, 0, MAX( co_variants[row_id] ), 1 ) = co_sectors[[#This Row],[sector_id]], co_variants[variant_label], "" ) )} -> Median, Low Confidence Interval, High Confidence Interval | J26: =_xlfn.TEXTJOIN( ", ", 1, OFFSET( INDIRECT( ADDRESS( ROW( INDEX( co_impactYears[sector_id], MATCH( co_sectors[[#This Row],[sector_id]], co_impactYears[sector_id], 0 ) ) ), COLUMN( co_impactYears[[#Headers],[sector_id]] ), , , "controlTables" ) ), 0, 1, 1, 4 ) ) -> N/A | K26: {=_xlfn.TEXTJOIN( ", ", 1, IF( OFFSET( INDIRECT( ADDRESS( ROW( co_impactTypes[[#Headers],[row_id]] ), COLUMN( co_impactTypes[[#Headers],[sector_id]] ), , , "controlTables" ) ), 1, 0, MAX( co_impactTypes[row_id] ), 1 ) = co_sectors[[#This Row],[sector_id]], co_impactTypes[impactType_label], "" ) )} -> N/A | L26: {=SUMPRODUCT( --( co_sectors[[#This Row],[sector_id]] = co_variants[sector_id] ) )} -> 3 | M26: {=SUMPRODUCT( --( co_sectors[[#This Row],[sector_id]] = co_impactTypes[sector_id] ) )} -> 1 | N26: {=IF( INDEX( co_impactYears[N/A], MATCH( 1, --( co_sectors[[#This Row],[sector_id]] = co_impactYears[sector_id] ), 0 ) ) = "N/A", 1, 2 )} -> 1 | O26: {=INDEX( co_modelTypes[Number of models], MATCH( 1, --( co_sectors[[#This Row],[modelType]] = co_modelTypes[modelType_id] ), 0 ) ) + IF( co_sectors[[#This Row],[modelType]] = "gcm", 1, 0 )} -> 9 | P26: {=INDEX( co_modelTypes[Number of levels], MATCH( 1, --( co_sectors[[#This Row],[modelType]] = co_modelTypes[modelType_id] ), 0 ) )} -> 7 | Q26: =PRODUCT( co_sectors[[#This Row],[Number of variants]:[Number of levels]] ) -> 189
B27: =ROW( co_sectors[[#This Row],[row_id]] ) - ROW( co_sectors[[#Headers],[row_id]] ) -> 7 | C27: CoastalProperties | D27: Coastal Properties | E27: 1 | F27: slr | G27: 0 | H27: {=IF( AND( SUMPRODUCT( co_impactYears[2010], --( co_sectors[[#This Row],[sector_id]] = co_impactYears[sector_id] ) ) > 1, SUMPRODUCT( co_impactYears[2090], --( co_sectors[[#This Row],[sector_id]] = co_impactYears[sector_id] ) ) > 1 ), 1, 0 )} -> 0 | I27: {=_xlfn.TEXTJOIN( ", ", 1, IF( OFFSET( INDIRECT( ADDRESS( ROW( co_variants[[#Headers],[row_id]] ), COLUMN( co_variants[[#Headers],[sector_id]] ), , , "controlTables" ) ), 1, 0, MAX( co_variants[row_id] ), 1 ) = co_sectors[[#This Row],[sector_id]], co_variants[variant_label], "" ) )} -> No Additional Adaptation, Proactive Adaptation, Reactive Adaptation | J27: =_xlfn.TEXTJOIN( ", ", 1, OFFSET( INDIRECT( ADDRESS( ROW( INDEX( co_impactYears[sector_id], MATCH( co_sectors[[#This Row],[sector_id]], co_impactYears[sector_id], 0 ) ) ), COLUMN( co_impactYears[[#Headers],[sector_id]] ), , , "controlTables" ) ), 0, 1, 1, 4 ) ) -> N/A | K27: {=_xlfn.TEXTJOIN( ", ", 1, IF( OFFSET( INDIRECT( ADDRESS( ROW( co_impactTypes[[#Headers],[row_id]] ), COLUMN( co_impactTypes[[#Headers],[sector_id]] ), , , "controlTables" ) ), 1, 0, MAX( co_impactTypes[row_id] ), 1 ) = co_sectors[[#This Row],[sector_id]], co_impactTypes[impactType_label], "" ) )} -> N/A | L27: {=SUMPRODUCT( --( co_sectors[[#This Row],[sector_id]] = co_variants[sector_id] ) )} -> 3 | M27: {=SUMPRODUCT( --( co_sectors[[#This Row],[sector_id]] = co_impactTypes[sector_id] ) )} -> 1 | N27: {=IF( INDEX( co_impactYears[N/A], MATCH( 1, --( co_sectors[[#This Row],[sector_id]] = co_impactYears[sector_id] ), 0 ) ) = "N/A", 1, 2 )} -> 1 | O27: {=INDEX( co_modelTypes[Number of models], MATCH( 1, --( co_sectors[[#This Row],[modelType]] = co_modelTypes[modelType_id] ), 0 ) ) + IF( co_sectors[[#This Row],[modelType]] = "gcm", 1, 0 )} -> 6 | P27: {=INDEX( co_modelTypes[Number of levels], MATCH( 1, --( co_sectors[[#This Row],[modelType]] = co_modelTypes[modelType_id] ), 0 ) )} -> 6 | Q27: =PRODUCT( co_sectors[[#This Row],[Number of variants]:[Number of levels]] ) -> 108
B28: =ROW( co_sectors[[#This Row],[row_id]] ) - ROW( co_sectors[[#Headers],[row_id]] ) -> 8 | C28: ElecSD | D28: Electricity Demand and Supply | E28: 1 | F28: gcm | G28: 0 | H28: {=IF( AND( SUMPRODUCT( co_impactYears[2010], --( co_sectors[[#This Row],[sector_id]] = co_impactYears[sector_id] ) ) > 1, SUMPRODUCT( co_impactYears[2090], --( co_sectors[[#This Row],[sector_id]] = co_impactYears[sector_id] ) ) > 1 ), 1, 0 )} -> 0 | I28: {=_xlfn.TEXTJOIN( ", ", 1, IF( OFFSET( INDIRECT( ADDRESS( ROW( co_variants[[#Headers],[row_id]] ), COLUMN( co_variants[[#Headers],[sector_id]] ), , , "controlTables" ) ), 1, 0, MAX( co_variants[row_id] ), 1 ) = co_sectors[[#This Row],[sector_id]], co_variants[variant_label], "" ) )} -> N/A | J28: =_xlfn.TEXTJOIN( ", ", 1, OFFSET( INDIRECT( ADDRESS( ROW( INDEX( co_impactYears[sector_id], MATCH( co_sectors[[#This Row],[sector_id]], co_impactYears[sector_id], 0 ) ) ), COLUMN( co_impactYears[[#Headers],[sector_id]] ), , , "controlTables" ) ), 0, 1, 1, 4 ) ) -> N/A | K28: {=_xlfn.TEXTJOIN( ", ", 1, IF( OFFSET( INDIRECT( ADDRESS( ROW( co_impactTypes[[#Headers],[row_id]] ), COLUMN( co_impactTypes[[#Headers],[sector_id]] ), , , "controlTables" ) ), 1, 0, MAX( co_impactTypes[row_id] ), 1 ) = co_sectors[[#This Row],[sector_id]], co_impactTypes[impactType_label], "" ) )} -> N/A | L28: {=SUMPRODUCT( --( co_sectors[[#This Row],[sector_id]] = co_variants[sector_id] ) )} -> 1 | M28: {=SUMPRODUCT( --( co_sectors[[#This Row],[sector_id]] = co_impactTypes[sector_id] ) )} -> 1 | N28: {=IF( INDEX( co_impactYears[N/A], MATCH( 1, --( co_sectors[[#This Row],[sector_id]] = co_impactYears[sector_id] ), 0 ) ) = "N/A", 1, 2 )} -> 1 | O28: {=INDEX( co_modelTypes[Number of models], MATCH( 1, --( co_sectors[[#This Row],[modelType]] = co_modelTypes[modelType_id] ), 0 ) ) + IF( co_sectors[[#This Row],[modelType]] = "gcm", 1, 0 )} -> 9 | P28: {=INDEX( co_modelTypes[Number of levels], MATCH( 1, --( co_sectors[[#This Row],[modelType]] = co_modelTypes[modelType_id] ), 0 ) )} -> 7 | Q28: =PRODUCT( co_sectors[[#This Row],[Number of variants]:[Number of levels]] ) -> 63
B29: =ROW( co_sectors[[#This Row],[row_id]] ) - ROW( co_sectors[[#Headers],[row_id]] ) -> 9 | C29: ElecTD | D29: Electricity Transmission and Distribution | E29: 1 | F29: gcm | G29: 1 | H29: {=IF( AND( SUMPRODUCT( co_impactYears[2010], --( co_sectors[[#This Row],[sector_id]] = co_impactYears[sector_id] ) ) > 1, SUMPRODUCT( co_impactYears[2090], --( co_sectors[[#This Row],[sector_id]] = co_impactYears[sector_id] ) ) > 1 ), 1, 0 )} -> 0 | I29: {=_xlfn.TEXTJOIN( ", ", 1, IF( OFFSET( INDIRECT( ADDRESS( ROW( co_variants[[#Headers],[row_id]] ), COLUMN( co_variants[[#Headers],[sector_id]] ), , , "controlTables" ) ), 1, 0, MAX( co_variants[row_id] ), 1 ) = co_sectors[[#This Row],[sector_id]], co_variants[variant_label], "" ) )} -> No Additional Adaptation, Proactive Adaptation, Reactive Adaptation | J29: =_xlfn.TEXTJOIN( ", ", 1, OFFSET( INDIRECT( ADDRESS( ROW( INDEX( co_impactYears[sector_id], MATCH( co_sectors[[#This Row],[sector_id]], co_impactYears[sector_id], 0 ) ) ), COLUMN( co_impactYears[[#Headers],[sector_id]] ), , , "controlTables" ) ), 0, 1, 1, 4 ) ) -> N/A | K29: {=_xlfn.TEXTJOIN( ", ", 1, IF( OFFSET( INDIRECT( ADDRESS( ROW( co_impactTypes[[#Headers],[row_id]] ), COLUMN( co_impactTypes[[#Headers],[sector_id]] ), , , "controlTables" ) ), 1, 0, MAX( co_impactTypes[row_id] ), 1 ) = co_sectors[[#This Row],[sector_id]], co_impactTypes[impactType_label], "" ) )} -> N/A | L29: {=SUMPRODUCT( --( co_sectors[[#This Row],[sector_id]] = co_variants[sector_id] ) )} -> 3 | M29: {=SUMPRODUCT( --( co_sectors[[#This Row],[sector_id]] = co_impactTypes[sector_id] ) )} -> 1 | N29: {=IF( INDEX( co_impactYears[N/A], MATCH( 1, --( co_sectors[[#This Row],[sector_id]] = co_impactYears[sector_id] ), 0 ) ) = "N/A", 1, 2 )} -> 1 | O29: {=INDEX( co_modelTypes[Number of models], MATCH( 1, --( co_sectors[[#This Row],[modelType]] = co_modelTypes[modelType_id] ), 0 ) ) + IF( co_sectors[[#This Row],[modelType]] = "gcm", 1, 0 )} -> 9 | P29: {=INDEX( co_modelTypes[Number of levels], MATCH( 1, --( co_sectors[[#This Row],[modelType]] = co_modelTypes[modelType_id] ), 0 ) )} -> 7 | Q29: =PRODUCT( co_sectors[[#This Row],[Number of variants]:[Number of levels]] ) -> 189
B30: =ROW( co_sectors[[#This Row],[row_id]] ) - ROW( co_sectors[[#Headers],[row_id]] ) -> 10 | C30: ExtremeTemp | D30: Extreme Temperature | E30: 1 | F30: gcm | G30: 0 | H30: {=IF( AND( SUMPRODUCT( co_impactYears[2010], --( co_sectors[[#This Row],[sector_id]] = co_impactYears[sector_id] ) ) > 1, SUMPRODUCT( co_impactYears[2090], --( co_sectors[[#This Row],[sector_id]] = co_impactYears[sector_id] ) ) > 1 ), 1, 0 )} -> 1 | I30: {=_xlfn.TEXTJOIN( ", ", 1, IF( OFFSET( INDIRECT( ADDRESS( ROW( co_variants[[#Headers],[row_id]] ), COLUMN( co_variants[[#Headers],[sector_id]] ), , , "controlTables" ) ), 1, 0, MAX( co_variants[row_id] ), 1 ) = co_sectors[[#This Row],[sector_id]], co_variants[variant_label], "" ) )} -> Adaptation, No Additional Adaptation | J30: =_xlfn.TEXTJOIN( ", ", 1, OFFSET( INDIRECT( ADDRESS( ROW( INDEX( co_impactYears[sector_id], MATCH( co_sectors[[#This Row],[sector_id]], co_impactYears[sector_id], 0 ) ) ), COLUMN( co_impactYears[[#Headers],[sector_id]] ), , , "controlTables" ) ), 0, 1, 1, 4 ) ) -> 2010, 2090 | K30: {=_xlfn.TEXTJOIN( ", ", 1, IF( OFFSET( INDIRECT( ADDRESS( ROW( co_impactTypes[[#Headers],[row_id]] ), COLUMN( co_impactTypes[[#Headers],[sector_id]] ), , , "controlTables" ) ), 1, 0, MAX( co_impactTypes[row_id] ), 1 ) = co_sectors[[#This Row],[sector_id]], co_impactTypes[impactType_label], "" ) )} -> Cold, Hot | L30: {=SUMPRODUCT( --( co_sectors[[#This Row],[sector_id]] = co_variants[sector_id] ) )} -> 2 | M30: {=SUMPRODUCT( --( co_sectors[[#This Row],[sector_id]] = co_impactTypes[sector_id] ) )} -> 2 | N30: {=IF( INDEX( co_impactYears[N/A], MATCH( 1, --( co_sectors[[#This Row],[sector_id]] = co_impactYears[sector_id] ), 0 ) ) = "N/A", 1, 2 )} -> 2 | O30: {=INDEX( co_modelTypes[Number of models], MATCH( 1, --( co_sectors[[#This Row],[modelType]] = co_modelTypes[modelType_id] ), 0 ) ) + IF( co_sectors[[#This Row],[modelType]] = "gcm", 1, 0 )} -> 9 | P30: {=INDEX( co_modelTypes[Number of levels], MATCH( 1, --( co_sectors[[#This Row],[modelType]] = co_modelTypes[modelType_id] ), 0 ) )} -> 7 | Q30: =PRODUCT( co_sectors[[#This Row],[Number of variants]:[Number of levels]] ) -> 504
B31: =ROW( co_sectors[[#This Row],[row_id]] ) - ROW( co_sectors[[#Headers],[row_id]] ) -> 11 | C31: HTF | D31: High Tide Flooding and Traffic | E31: 1 | F31: slr | G31: 1 | H31: {=IF( AND( SUMPRODUCT( co_impactYears[2010], --( co_sectors[[#This Row],[sector_id]] = co_impactYears[sector_id] ) ) > 1, SUMPRODUCT( co_impactYears[2090], --( co_sectors[[#This Row],[sector_id]] = co_impactYears[sector_id] ) ) > 1 ), 1, 0 )} -> 0 | I31: {=_xlfn.TEXTJOIN( ", ", 1, IF( OFFSET( INDIRECT( ADDRESS( ROW( co_variants[[#Headers],[row_id]] ), COLUMN( co_variants[[#Headers],[sector_id]] ), , , "controlTables" ) ), 1, 0, MAX( co_variants[row_id] ), 1 ) = co_sectors[[#This Row],[sector_id]], co_variants[variant_label], "" ) )} -> Direct Adaptation, No Additional Adaptation, Reasonably Anticipated Adaptation | J31: =_xlfn.TEXTJOIN( ", ", 1, OFFSET( INDIRECT( ADDRESS( ROW( INDEX( co_impactYears[sector_id], MATCH( co_sectors[[#This Row],[sector_id]], co_impactYears[sector_id], 0 ) ) ), COLUMN( co_impactYears[[#Headers],[sector_id]] ), , , "controlTables" ) ), 0, 1, 1, 4 ) ) -> N/A | K31: {=_xlfn.TEXTJOIN( ", ", 1, IF( OFFSET( INDIRECT( ADDRESS( ROW( co_impactTypes[[#Headers],[row_id]] ), COLUMN( co_impactTypes[[#Headers],[sector_id]] ), , , "controlTables" ) ), 1, 0, MAX( co_impactTypes[row_id] ), 1 ) = co_sectors[[#This Row],[sector_id]], co_impactTypes[impactType_label], "" ) )} -> N/A | L31: {=SUMPRODUCT( --( co_sectors[[#This Row],[sector_id]] = co_variants[sector_id] ) )} -> 3 | M31: {=SUMPRODUCT( --( co_sectors[[#This Row],[sector_id]] = co_impactTypes[sector_id] ) )} -> 1 | N31: {=IF( INDEX( co_impactYears[N/A], MATCH( 1, --( co_sectors[[#This Row],[sector_id]] = co_impactYears[sector_id] ), 0 ) ) = "N/A", 1, 2 )} -> 1 | O31: {=INDEX( co_modelTypes[Number of models], MATCH( 1, --( co_sectors[[#This Row],[modelType]] = co_modelTypes[modelType_id] ), 0 ) ) + IF( co_sectors[[#This Row],[modelType]] = "gcm", 1, 0 )} -> 6 | P31: {=INDEX( co_modelTypes[Number of levels], MATCH( 1, --( co_sectors[[#This Row],[modelType]] = co_modelTypes[modelType_id] ), 0 ) )} -> 6 | Q31: =PRODUCT( co_sectors[[#This Row],[Number of variants]:[Number of levels]] ) -> 108
B32: =ROW( co_sectors[[#This Row],[row_id]] ) - ROW( co_sectors[[#Headers],[row_id]] ) -> 12 | C32: InlandFlooding | D32: Inland Flooding | E32: 1 | F32: gcm | G32: 0 | H32: {=IF( AND( SUMPRODUCT( co_impactYears[2010], --( co_sectors[[#This Row],[sector_id]] = co_impactYears[sector_id] ) ) > 1, SUMPRODUCT( co_impactYears[2090], --( co_sectors[[#This Row],[sector_id]] = co_impactYears[sector_id] ) ) > 1 ), 1, 0 )} -> 0 | I32: {=_xlfn.TEXTJOIN( ", ", 1, IF( OFFSET( INDIRECT( ADDRESS( ROW( co_variants[[#Headers],[row_id]] ), COLUMN( co_variants[[#Headers],[sector_id]] ), , , "controlTables" ) ), 1, 0, MAX( co_variants[row_id] ), 1 ) = co_sectors[[#This Row],[sector_id]], co_variants[variant_label], "" ) )} -> N/A | J32: =_xlfn.TEXTJOIN( ", ", 1, OFFSET( INDIRECT( ADDRESS( ROW( INDEX( co_impactYears[sector_id], MATCH( co_sectors[[#This Row],[sector_id]], co_impactYears[sector_id], 0 ) ) ), COLUMN( co_impactYears[[#Headers],[sector_id]] ), , , "controlTables" ) ), 0, 1, 1, 4 ) ) -> N/A | K32: {=_xlfn.TEXTJOIN( ", ", 1, IF( OFFSET( INDIRECT( ADDRESS( ROW( co_impactTypes[[#Headers],[row_id]] ), COLUMN( co_impactTypes[[#Headers],[sector_id]] ), , , "controlTables" ) ), 1, 0, MAX( co_impactTypes[row_id] ), 1 ) = co_sectors[[#This Row],[sector_id]], co_impactTypes[impactType_label], "" ) )} -> N/A | L32: {=SUMPRODUCT( --( co_sectors[[#This Row],[sector_id]] = co_variants[sector_id] ) )} -> 1 | M32: {=SUMPRODUCT( --( co_sectors[[#This Row],[sector_id]] = co_impactTypes[sector_id] ) )} -> 1 | N32: {=IF( INDEX( co_impactYears[N/A], MATCH( 1, --( co_sectors[[#This Row],[sector_id]] = co_impactYears[sector_id] ), 0 ) ) = "N/A", 1, 2 )} -> 1 | O32: {=INDEX( co_modelTypes[Number of models], MATCH( 1, --( co_sectors[[#This Row],[modelType]] = co_modelTypes[modelType_id] ), 0 ) ) + IF( co_sectors[[#This Row],[modelType]] = "gcm", 1, 0 )} -> 9 | P32: {=INDEX( co_modelTypes[Number of levels], MATCH( 1, --( co_sectors[[#This Row],[modelType]] = co_modelTypes[modelType_id] ), 0 ) )} -> 7 | Q32: =PRODUCT( co_sectors[[#This Row],[Number of variants]:[Number of levels]] ) -> 63
... B45: =ROW( co_sectors[[#This Row],[row_id]] ) - ROW( co_sectors[[#Headers],[row_id]] ) -> 25 | C45: WinterRec | D45: Winter Recreation | E45: 1 | F45: gcm | G45: 0 | H45: {=IF( AND( SUMPRODUCT( co_impactYears[2010], --( co_sectors[[#This Row],[sector_id]] = co_impactYears[sector_id] ) ) > 1, SUMPRODUCT( co_impactYears[2090], --( co_sectors[[#This Row],[sector_id]] = co_impactYears[sector_id] ) ) > 1 ), 1, 0 )} -> 1 | I45: {=_xlfn.TEXTJOIN( ", ", 1, IF( OFFSET( INDIRECT( ADDRESS( ROW( co_variants[[#Headers],[row_id]] ), COLUMN( co_variants[[#Headers],[sector_id]] ), , , "controlTables" ) ), 1, 0, MAX( co_variants[row_id] ), 1 ) = co_sectors[[#This Row],[sector_id]], co_variants[variant_label], "" ) )} -> N/A | J45: =_xlfn.TEXTJOIN( ", ", 1, OFFSET( INDIRECT( ADDRESS( ROW( INDEX( co_impactYears[sector_id], MATCH( co_sectors[[#This Row],[sector_id]], co_impactYears[sector_id], 0 ) ) ), COLUMN( co_impactYears[[#Headers],[sector_id]] ), , , "controlTables" ) ), 0, 1, 1, 4 ) ) -> 2010, 2090 | K45: {=_xlfn.TEXTJOIN( ", ", 1, IF( OFFSET( INDIRECT( ADDRESS( ROW( co_impactTypes[[#Headers],[row_id]] ), COLUMN( co_impactTypes[[#Headers],[sector_id]] ), , , "controlTables" ) ), 1, 0, MAX( co_impactTypes[row_id] ), 1 ) = co_sectors[[#This Row],[sector_id]], co_impactTypes[impactType_label], "" ) )} -> Alpine Skiing, Cross-Country Skiing, Snowmobiling | L45: {=SUMPRODUCT( --( co_sectors[[#This Row],[sector_id]] = co_variants[sector_id] ) )} -> 1 | M45: {=SUMPRODUCT( --( co_sectors[[#This Row],[sector_id]] = co_impactTypes[sector_id] ) )} -> 3 | N45: {=IF( INDEX( co_impactYears[N/A], MATCH( 1, --( co_sectors[[#This Row],[sector_id]] = co_impactYears[sector_id] ), 0 ) ) = "N/A", 1, 2 )} -> 2 | O45: {=INDEX( co_modelTypes[Number of models], MATCH( 1, --( co_sectors[[#This Row],[modelType]] = co_modelTypes[modelType_id] ), 0 ) ) + IF( co_sectors[[#This Row],[modelType]] = "gcm", 1, 0 )} -> 9 | P45: {=INDEX( co_modelTypes[Number of levels], MATCH( 1, --( co_sectors[[#This Row],[modelType]] = co_modelTypes[modelType_id] ), 0 ) )} -> 7 | Q45: =PRODUCT( co_sectors[[#This Row],[Number of variants]:[Number of levels]] ) -> 378
B47: Impact Year Estimates
B49: row_id | C49: sector_id | D49: N/A | E49: 2010 | F49: 2090
B50: =ROW( co_impactYears[[#This Row],[row_id]] ) - ROW(co_impactYears[[#Headers],[row_id]] ) -> 1 | C50: AirQuality | D50: {=IF( SUMPRODUCT( --( VALUE( controlTables!E$49 ) = data_scaledImpacts[impactYear] ), --( co_impactYears[[#This Row],[sector_id]] = data_scaledImpacts[sector] ) ) > 0, "", controlTables!D$49 )} -> N/A | E50: {=IF( SUMPRODUCT( --( VALUE( controlTables!E$49 ) = data_scaledImpacts[impactYear] ), --( co_impactYears[[#This Row],[sector_id]] = data_scaledImpacts[sector] ) ) > 0, VALUE( controlTables!E$49 ), "" )} | F50: {=IF( SUMPRODUCT( --( VALUE( controlTables!F$49 ) = data_scaledImpacts[impactYear] ), --( co_impactYears[[#This Row],[sector_id]] = data_scaledImpacts[sector] ) ) > 0, VALUE( controlTables!F$49 ), "" )}
